BUG REPORT COMMENTS:
Using warm-up build I20070205-0009 and taken example given in buildnotes for bug 157584, I got an NPE while completing in catch formal parameter.

Here's the test case I used:
package bug;
public class X {
  void foo() throws TestException, TestOtherException {}
  void bar() {
    try {
    	foo();
    } catch(TestException e) {
    } catch(Test|) //complete at '|' position
  }
}
class TestException extends Exception {}
class TestOtherException extends Exception {}

Then you'll get an NPE with following stack trace:
java.lang.NullPointerException
	at org.eclipse.jdt.internal.compiler.lookup.ReferenceBinding.canBeSeenBy(ReferenceBinding.java:254)
	at org.eclipse.jdt.internal.codeassist.CompletionEngine.findExceptionFromTryStatement(CompletionEngine.java:2321)
	at org.eclipse.jdt.internal.codeassist.CompletionEngine.findExceptionFromTryStatement(CompletionEngine.java:2469)
	at org.eclipse.jdt.internal.codeassist.CompletionEngine.complete(CompletionEngine.java:936)
	at org.eclipse.jdt.internal.codeassist.Complet

